<?xml version="1.0"?>
<robot xmlns:xacro="http://ros.org/wiki/xacro">
  <xacro:include filename="$(find balancingkit_description)/urdf/wheel/wheel.transmission.xacro"/>
  <xacro:include filename="$(find balancingkit_description)/urdf/wheel/wheel.gazebo.xacro"/>
  <property name="wheel_radius" value="0.03825"/>
  <property name="wheel_length" value="0.01"/> <!-- width? -->
  <property name="wheel_mass" value="0.0192200809141"/>
  <xacro:macro name="wheel" params="prefix parent *joint_origin *joint_axis">
  <joint name="${prefix}_wheel_joint" type="continuous">
    <insert_block name="joint_origin"/>
    <insert_block name="joint_axis"/>
    <parent link="${parent}"/>
    <child link="${prefix}_wheel"/>
    <limit effort="70" velocity="15"/> <!-- TODO Need to calculate -->
    <safety_controller  k_velocity="10" />
    <dynamics damping="1.0" friction="1.0" />
  </joint>
  <link name="${prefix}_wheel">
    <visual>
      <geometry>
        <mesh filename="package://balancingkit_description/meshes/stl/wheel/balboa_balancing_robot_kit_wheel_${prefix}_m.stl"/>
      </geometry>
    </visual>
    <collision>
      <!-- <insert_block name="joint_origin"/> -->
        <geometry>
          <mesh filename="package://balancingkit_description/meshes/stl/wheel/balboa_balancing_robot_kit_wheel_${prefix}_m.stl"/>
        </geometry>
    </collision>
      <inertial>
        <mass value="${wheel_mass}"/>
        <inertia ixx="0.000021836231232000" ixy="0.000000000014016411" ixz="-0.000000000002704489" iyy="0.000011052671184900" iyz="-0.000000000002905832" izz="0.000011048923704800" />
      </inertial>
  </link>
  </xacro:macro>
</robot>
